# 一、设计模式

# 二、异常处理

> Python中（至少）有两种错误：语法错误和异常（syntax errors 和 exceptions）.

    1. 语法错误
       语法错误，也被称作解析错误，也许是你学习 Python 过程中最常见抱怨:
            >>> while True print('Hello world')
            File "<stdin>", line 1, in ?
            while True print('Hello world')
                         ^
            SyntaxError: invalid syntax

    2. 异常
       即使一条语句或表达式在语法上是正确的，当试图执行它时也可能会引发错误。运行期检测到的错误称为`异常`，并且程序不会无条件的崩溃,大多数异常都不会       <br/>被程序处理，像这里展示的一样最终会产生一个错误信息:
                >>> 10 * (1/0)
                Traceback (most recent call last):
                File "<stdin>", line 1, in ?
                ZeroDivisionError: int division or modulo by zero
                >>> 4 + spam*3
                Traceback (most recent call last):
                File "<stdin>", line 1, in ?
                NameError: name 'spam' is not defined
                >>> '2' + 2
                Traceback (most recent call last):
                File "<stdin>", line 1, in ?
                TypeError: Can't convert 'int' object to str implicitly

> 错误信息的最后一行指出发生了什么错误。异常也有不同的类型，异常类型做为错误信息的一部分显示出来：示例中的异常分别为 零除错误（ ZeroDivisionError ） ，命名错误（ NameError） 和 类型错误（ TypeError ）。打印错误信息时，异常的类型作为异常的内置名显示。对于所有的内置异常都是如此，不过用户自定义异常就不一定了（尽管这是一个很有用的约定）。标准异常名是内置的标识（没有保留关键字）。

### 2.1 异常处理try...excpet...finally ###

>异常处理在任何一门编程语言里都是值得关注的一个话题，良好的异常处理可以让你的程序更加健壮，清晰的错误信息更能帮助你快速修复问题。

```Python
def div(a, b):
    try:
        print(a / b)
    except ZeroDivisionError:
        print("Error: b should not be 0 !!")
    except Exception as e:
        print("Unexpected Error: {}".format(e))
    else:
        print('Run into else only when everything goes well')
    finally:
        print('Always run into finally block.')

# tests
div(2, 0)
div(2, 'bad type')
div(1, 2)

# Mutiple exception in one line
try:
    print(a / b)
except (ZeroDivisionError, TypeError) as e:
    print(e)

# Except block is optional when there is finally
try:
    open(database)
finally:
    close(database)

# catch all errors and log it
try:
    do_work()
except:    
    # get detail from logging module
    logging.exception('Exception caught!')
    
    # get detail from sys.exc_info() method
    error_type, error_value, trace_back = sys.exc_info()
    print(error_value)
    raise
```


    1.except语句不是必须的，finally语句也不是必须的，但是二者必须要有一个，否则就没有try的意义了。
    2.except语句可以有多个，Python会按except语句的顺序依次匹配你指定的异常，如果异常已经处理就不会再进入后面的except语句。
    3.except语句可以以元组形式同时指定多个异常，参见实例代码。
    4.except语句后面如果不指定异常类型，则默认捕获所有异常，你可以通过logging或者sys模块获取当前异常。
    5.如果要捕获异常后要重复抛出，请使用raise，后面不要带任何参数或信息。
    6.不建议捕获并抛出同一个异常，请考虑重构你的代码。
    7.不建议在不清楚逻辑的情况下捕获所有异常，有可能你隐藏了很严重的问题。
    8.尽量使用内置的异常处理语句来替换try/except语句，比如with语句，getattr()方法。

### 2.2 抛出异常raise ###

如果你需要自主抛出异常一个异常，可以使用raise关键字，等同于C#和Java中的throw，其语法规则如下：

```Python
raise NameError("bad name!")
```

raise关键字后面可以指定你要抛出的异常实例，一般来说抛出的异常越详细越好，Python在exceptions模块内建了很多的异常类型，通过使用dir()函数来查看exceptions中的异常类型，如下：

```Python
import exceptions

print dir(exceptions)
# ['ArithmeticError', 'AssertionError'...]
```


### 2.3 自定义异常类型 ###

Python中自定义自己的异常类型非常简单，只需要要从Exception类继承即可(直接或间接)：

```Python
class SomeCustomException(Exception):
    pass

class AnotherException(SomeCustomException):
    pass
```

一般你在自定义异常类型时，需要考虑的问题应该是这个异常所应用的场景。如果内置异常已经包括了你需要的异常，建议考虑使用内置的异常类型。比如你希望在函数参数错误时抛出一个异常，你可能并不需要定义一个InvalidArgumentError，使用内置的ValueError即可。

### 2.4 定义清理行为 ###

try 语句还有另一个可选的子句，目的在于定义在任何情况下都一定要执行的功能。例如:

```Python
>>> try:
...     raise KeyboardInterrupt
... finally:
...     print('Goodbye, world!')
...
Goodbye, world!
KeyboardInterrupt
Traceback (most recent call last):
  File "<stdin>", line 2, in ?
```

不管有没有发生异常，finally子句 在程序离开 try 后都一定会被执行。当 try 语句中发生了未被 except 捕获的异常（或者它发生在 except 或 else 子句中），在 finally 子句执行完后它会被重新抛出。 try 语句经由 break ，continue 或 return 语句退 出也一样会执行 finally 子句。以下是一个更复杂些的例子:

```Python
>>> def divide(x, y):
...     try:
...         result = x / y
...     except ZeroDivisionError:
...         print("division by zero!")
...     else:
...         print("result is", result)
...     finally:
...         print("executing finally clause")
...
>>> divide(2, 1)
result is 2
executing finally clause
>>> divide(2, 0)
division by zero!
executing finally clause
>>> divide("2", "1")
executing finally clause
Traceback (most recent call last):
  File "<stdin>", line 1, in ?
  File "<stdin>", line 3, in divide
TypeError: unsupported operand type(s) for /: 'str' and 'str'
```

如你所见， finally 子句在任何情况下都会执行。TypeError 在两个字符串相除的时候抛出，未被 except 子句捕获，因此在 finally 子句执行完毕后重新抛出。

在真实场景的应用程序中，finally 子句用于释放外部资源（文件 或网络连接之类的），无论它们的使用过程中是否出错。

### 2.5 预定义清理行为 ###

有些对象定义了标准的清理行为，无论对象操作是否成功，不再需要该对象的时候就会起作用。以下示例尝试打开文件并把内容打印到屏幕上。

```Python
for line in open("myfile.txt"):
    print(line)
```

这段代码的问题在于在代码执行完后没有立即关闭打开的文件。这在简单的脚本里没什么，但是大型应用程序就会出问题。with 语句使得文件之类的对象可以 确保总能及时准确地进行清理。

```Python
with open("myfile.txt") as f:
    for line in f:
        print(line)
```

语句执行后，文件 f 总会被关闭，即使是在处理文件中的数据时出错也一样。其它对象是否提供了预定义的清理行为要查看它们的文档。

### 2.6 经典案例 ###

1. 传递异常 re-raise Exception

2. Exception 和 BaseException


3. except Exception as e和 except Exception, e


4. raise "Exception string"


5. 使用内置的语法范式代替try/except



### 2.7 最佳实践 ###


    1.只处理你知道的异常，避免捕获所有异常然后吞掉它们。
    2.抛出的异常应该说明原因，有时候你知道异常类型也猜不出所以然。
    3.避免在catch语句块中干一些没意义的事情，捕获异常也是需要成本的。
    4.不要使用异常来控制流程，那样你的程序会无比难懂和难维护。
    5.如果有需要，切记使用finally来释放资源。
    6.如果有需要，请不要忘记在处理异常后做清理工作或者回滚操作。

